Workbook

Sheet g1
B1: pt | C1: rb | D1: ast | E1: blk | F1: stl | G1: fgm | H1: fga | I1: 3m | J1: 3a | K1: ftm | L1: fta | M1: rbo | N1: fl | O1: to | P1: +-
A2: G1
A3: NO | B3: pt | C3: rb | D3: ast | E3: blk | F3: stl | G3: fgm | H3: fga | I3: 3m | J3: 3a | K3: ftm | L3: fta | M3: rbo | N3: fl | O3: to | P3: +-
A4: Lonzo Ball | B4: =G4*2+I4+K4 -> 9 | C4: 1 | D4: 2 | E4: 1 | F4: 1 | G4: 3 | H4: 10 | I4: 3 | J4: 6 | K4: 0 | L4: 0 | M4: 0 | N4: 6 | O4: 1 | P4: 5
A5: N.A.Walker | B5: =G5*2+I5+K5 -> 40 | C5: 9 | D5: 8 | E5: 0 | F5: 2 | G5: 13 | H5: 24 | I5: 6 | J5: 14 | K5: 8 | L5: 9 | M5: 2 | N5: 2 | O5: 2 | P5: -4
A6: B.Ingram | B6: =G6*2+I6+K6 -> 18 | C6: 5 | D6: 10 | E6: 2 | F6: 0 | G6: 7 | H6: 16 | I6: 1 | J6: 3 | K6: 3 | L6: 4 | M6: 1 | N6: 2 | O6: 2 | P6: -11
A7: Z.Williamson | B7: =G7*2+I7+K7 -> 11 | C7: 6 | D7: 1 | E7: 3 | F7: 1 | G7: 5 | H7: 8 | I7: 1 | J7: 2 | K7: 0 | L7: 1 | M7: 1 | N7: 6 | O7: 1 | P7: 3
A8: A.Drummond | B8: =G8*2+I8+K8 -> 19 | C8: 22 | D8: 2 | E8: 0 | F8: 1 | G8: 9 | H8: 12 | I8: 0 | J8: 0 | K8: 1 | L8: 2 | M8: 11 | N8: 1 | O8: 0 | P8: -3
A9: J.Holiday | B9: =G9*2+I9+K9 -> 15 | C9: 4 | D9: 4 | E9: 0 | F9: 1 | G9: 7 | H9: 15 | I9: 1 | J9: 3 | K9: 0 | L9: 0 | M9: 0 | N9: 2 | O9: 2 | P9: 1
A10: S.Mcdaniels | B10: =G10*2+I10+K10 -> 6 | C10: 2 | D10: 2 | E10: 0 | F10: 0 | G10: 2 | H10: 7 | I10: 1 | J10: 1 | K10: 1 | L10: 2 | M10: 0 | N10: 1 | O10: 4 | P10: -14
A11: J.Hart | B11: =G11*2+I11+K11 -> 6 | C11: 0 | D11: 0 | E11: 1 | F11: 2 | G11: 3 | H11: 8 | I11: 0 | J11: 2 | K11: 0 | L11: 0 | M11: 0 | N11: 0 | O11: 2 | P11: -7
A12: D.Gallinari | B12: =G12*2+I12+K12 -> 4 | C12: 2 | D12: 1 | E12: 1 | F12: 3 | G12: 1 | H12: 3 | I12: 1 | J12: 2 | K12: 1 | L12: 1 | M12: 0 | N12: 1 | O12: 0 | P12: 2
A13: CLE | B13: pt | C13: rb | D13: ast | E13: blk | F13: stl | G13: fgm | H13: fga | I13: 3m | J13: 3a | K13: ftm | L13: fta | M13: rbo | N13: fl | O13: to | P13: +-
A14: S.G.Alexander | B14: =G14*2+I14+K14 -> 53 | C14: 2 | D14: 4 | E14: 2 | F14: 1 | G14: 17 | H14: 24 | I14: 1 | J14: 1 | K14: 18 | L14: 18 | M14: 0 | N14: 5 | O14: 2 | P14: 13
A15: D.Mitchell | B15: =G15*2+I15+K15 -> 34 | C15: 4 | D15: 6 | E15: 1 | F15: 1 | G15: 12 | H15: 21 | I15: 0 | J15: 1 | K15: 10 | L15: 10 | M15: 0 | N15: 5 | O15: 2 | P15: 9
A16: D.Booker | B16: =G16*2+I16+K16 -> 12 | C16: 8 | D16: 10 | E16: 0 | F16: 1 | G16: 4 | H16: 15 | I16: 4 | J16: 8 | K16: 0 | L16: 0 | M16: 0 | N16: 4 | O16: 0 | P16: 18
A17: M.Robinson | B17: =G17*2+I17+K17 -> 8 | C17: 8 | D17: 8 | E17: 4 | F17: 0 | G17: 2 | H17: 8 | I17: 0 | J17: 0 | K17: 4 | L17: 5 | M17: 3 | N17: 1 | O17: 1 | P17: 10
A18: W.Chamberlain | B18: =G18*2+I18+K18 -> 6 | C18: 11 | D18: 3 | E18: 2 | F18: 2 | G18: 3 | H18: 3 | I18: 0 | J18: 0 | K18: 0 | L18: 1 | M18: 2 | N18: 4 | O18: 1 | P18: 20
A19: J.Brown | B19: =G19*2+I19+K19 -> 15 | C19: 6 | D19: 2 | E19: 0 | F19: 1 | G19: 6 | H19: 10 | I19: 0 | J19: 2 | K19: 3 | L19: 3 | M19: 0 | N19: 2 | O19: 1 | P19: -4
A20: T.Rozier III | B20: =G20*2+I20+K20 -> 5 | C20: 1 | D20: 2 | E20: 1 | F20: 0 | G20: 2 | H20: 2 | I20: 0 | J20: 0 | K20: 1 | L20: 2 | M20: 0 | N20: 1 | O20: 2 | P20: -11
A21: M.Wagner | B21: =G21*2+I21+K21 -> 4 | C21: 3 | D21: 1 | E21: 3 | F21: 0 | G21: 2 | H21: 2 | I21: 0 | J21: 1 | K21: 0 | L21: 0 | M21: 0 | N21: 0 | O21: 0 | P21: 2
A22: E.Schmidt | B22: =G22*2+I22+K22 -> 2 | C22: 1 | D22: 3 | E22: 0 | F22: 0 | G22: 1 | H22: 2 | I22: 0 | J22: 0 | K22: 0 | L22: 0 | M22: 0 | N22: 0 | O22: 3 | P22: 8
A23: Total
A24: NO | B24: =G24*2+I24+K24 -> 128 | C24: =SUM(C4:C12) -> 51 | D24: =SUM(D4:D12) -> 30 | E24: =SUM(E4:E12) -> 8 | F24: =SUM(F4:F12) -> 11 | G24: =SUM(G4:G12) -> 50 | H24: =SUM(H4:H12) -> 103 | I24: =SUM(I4:I12) -> 14 | J24: =SUM(J4:J12) -> 33 | ... O24: =SUM(O4:O12) -> 14
A25: CLE | B25: =G25*2+I25+K25 -> 139 | C25: =SUM(C14:C22) -> 44 | D25: =SUM(D14:D22) -> 39 | E25: =SUM(E14:E22) -> 13 | F25: =SUM(F14:F22) -> 6 | G25: =SUM(G14:G22) -> 49 | H25: =SUM(H14:H22) -> 87 | I25: =SUM(I14:I22) -> 5 | J25: =SUM(J14:J22) -> 13 | ... O25: =SUM(O14:O22) -> 12
A29: G2
A30: NO | B30: pt | C30: rb | D30: ast | E30: blk | F30: stl | G30: fgm | H30: fga | I30: 3m | J30: 3a | K30: ftm | L30: fta | M30: rbo | N30: fl | O30: to | P30: +-
A31: Lonzo Ball | B31: =G31*2+I31+K31 -> 24 | C31: 6 | D31: 3 | E31: 4 | F31: 0 | G31: 11 | H31: 16 | I31: 2 | J31: 6 | K31: 0 | L31: 2 | M31: 0 | N31: 6 | O31: 1 | P31: 16
A32: N.A.Walker | B32: =G32*2+I32+K32 -> 27 | C32: 5 | D32: 7 | E32: 2 | F32: 0 | G32: 11 | H32: 20 | I32: 3 | J32: 6 | K32: 2 | L32: 2 | M32: 1 | N32: 6 | O32: 0 | P32: -3
A33: B.Ingram | B33: =G33*2+I33+K33 -> 21 | C33: 8 | D33: 17 | E33: 1 | F33: 1 | G33: 8 | H33: 15 | I33: 1 | J33: 2 | K33: 4 | L33: 8 | M33: 2 | N33: 2 | O33: 4 | P33: -4
A34: Z.Williamson | B34: =G34*2+I34+K34 -> 14 | C34: 13 | D34: 3 | E34: 2 | F34: 1 | G34: 7 | H34: 13 | I34: 0 | J34: 0 | K34: 0 | L34: 2 | M34: 6 | N34: 6 | O34: 1 | P34: 3
A35: A.Drummond | B35: =G35*2+I35+K35 -> 29 | C35: 21 | D35: 7 | E35: 2 | F35: 3 | G35: 13 | H35: 23 | I35: 0 | J35: 0 | K35: 3 | L35: 4 | M35: =9 -> 9 | N35: 3 | O35: 1 | P35: -10
A36: J.Holiday | B36: =G36*2+I36+K36 -> 24 | C36: 3 | D36: 6 | E36: 2 | F36: 4 | G36: 9 | H36: 26 | I36: 1 | J36: 11 | K36: 5 | L36: 6 | M36: 1 | N36: 2 | O36: 3 | P36: -9
A37: S.Mcdaniels | B37: =G37*2+I37+K37 -> 26 | C37: 1 | D37: 6 | E37: 0 | F37: 5 | G37: 10 | H37: 19 | I37: 2 | J37: 5 | K37: 4 | L37: 6 | M37: 1 | N37: 6 | O37: 5 | P37: -10
A38: J.Hart | B38: =G38*2+I38+K38 -> 18 | C38: 2 | D38: 2 | E38: 0 | F38: 1 | G38: 6 | H38: 11 | I38: 2 | J38: 5 | K38: 4 | L38: 4 | M38: 1 | N38: 4 | O38: 1 | P38: 0
A39: D.Gallinari | B39: =G39*2+I39+K39 -> 3 | C39: 1 | D39: 0 | E39: 0 | F39: 1 | G39: 1 | H39: 2 | I39: 1 | J39: 2 | K39: 0 | L39: 0 | M39: 0 | N39: 2 | O39: 1 | P39: -10
A40: CLE | B40: pt | C40: rb | D40: ast | E40: blk | F40: stl | G40: fgm | H40: fga | I40: 3m | J40: 3a | K40: ftm | L40: fta | M40: rbo | N40: fl | O40: to | P40: +-
A41: S.G.Alexander | B41: =G41*2+I41+K41 -> 76 | C41: 5 | D41: 5 | E41: 3 | F41: 7 | G41: 24 | H41: 40 | I41: 0 | J41: 0 | K41: 28 | L41: 28 | M41: 1 | N41: 5 | O41: 4 | P41: 20
A42: D.Mitchell | B42: =G42*2+I42+K42 -> 29 | C42: 5 | D42: 13 | E42: 3 | F42: 2 | G42: 10 | H42: 30 | I42: 1 | J42: 2 | K42: 8 | L42: 11 | M42: 1 | N42: 6 | O42: 4 | P42: 12
A43: D.Booker | B43: =G43*2+I43+K43 -> 11 | C43: 13 | D43: 7 | E43: 3 | F43: 1 | G43: 4 | H43: 9 | I43: 1 | J43: 3 | K43: 2 | L43: 3 | M43: 0 | N43: 6 | O43: 0 | P43: 0
...

Sheet Sheet2
A1: S.G.Alexander | U1: ---
A2: game | B2: 得分 | C2: 篮板 | D2: 助攻 | E2: 盖帽 | F2: 抢断 | G2: FGM | H2: FGA | I2: FG% | J2: 3PTM | K2: 3PTA | L2: 3PT% | M2: FTM | N2: FTA | O2: FT% | P2: 进攻篮板 | Q2: 犯规 | R2: 失误 | S2: 正负值/分差 | U2: ---
A3: ='g1'!A14 -> S.G.Alexander | B3: ='g1'!B14 -> 53 | C3: ='g1'!C14 -> 2 | D3: ='g1'!D14 -> 4 | E3: ='g1'!E14 -> 2 | F3: ='g1'!F14 -> 1 | G3: ='g1'!G14 -> 17 | H3: ='g1'!H14 -> 24 | I3: =IF(H3,G3/H3*100,U1) -> 70.833333 | J3: ='g1'!I14 -> 1 | K3: ='g1'!J14 -> 1 | L3: =IF(K3,J3/K3*100,U1) -> 100 | M3: ='g1'!K14 -> 18 | N3: ='g1'!L14 -> 18 | O3: =IF(N3,M3/N3*100,U1) -> 100 | P3: ='g1'!M14 -> 0 | Q3: ='g1'!N14 -> 5 | R3: ='g1'!O14 -> 2 | S3: ='g1'!P14 -> 13 | U3: ---
A4: ='g1'!A41 -> S.G.Alexander | B4: ='g1'!B41 -> 76 | C4: ='g1'!C41 -> 5 | D4: ='g1'!D41 -> 5 | E4: ='g1'!E41 -> 3 | F4: ='g1'!F41 -> 7 | G4: ='g1'!G41 -> 24 | H4: ='g1'!H41 -> 40 | I4: =IF(H4,G4/H4*100,U2) -> 60 | J4: ='g1'!I41 -> 0 | K4: ='g1'!J41 -> 0 | L4: =IF(K4,J4/K4*100,U2) -> --- | M4: ='g1'!K41 -> 28 | N4: ='g1'!L41 -> 28 | O4: =IF(N4,M4/N4*100,U2) -> 100 | P4: ='g1'!M41 -> 1 | Q4: ='g1'!N41 -> 5 | R4: ='g1'!O41 -> 4 | S4: ='g1'!P41 -> 20 | U4: ---
A5: ='g1'!A68 -> S.G.Alexander | B5: ='g1'!B68 -> 29 | C5: ='g1'!C68 -> 9 | D5: ='g1'!D68 -> 9 | E5: ='g1'!E68 -> 4 | F5: ='g1'!F68 -> 3 | G5: ='g1'!G68 -> 8 | H5: ='g1'!H68 -> 18 | I5: =IF(H5,G5/H5*100,U3) -> 44.444444 | J5: ='g1'!I68 -> 0 | K5: ='g1'!J68 -> 1 | L5: =IF(K5,J5/K5*100,U3) -> 0 | M5: ='g1'!K68 -> 13 | N5: ='g1'!L68 -> 15 | O5: =IF(N5,M5/N5*100,U3) -> 86.666667 | P5: ='g1'!M68 -> 2 | Q5: ='g1'!N68 -> 6 | R5: ='g1'!O68 -> 5 | S5: ='g1'!P68 -> 10 | U5: ---
A6: ='g1'!A95 -> S.G.Alexander | B6: ='g1'!B95 -> 47 | C6: ='g1'!C95 -> 1 | D6: ='g1'!D95 -> 1 | E6: ='g1'!E95 -> 0 | F6: ='g1'!F95 -> 1 | G6: ='g1'!G95 -> 20 | H6: ='g1'!H95 -> 29 | I6: =IF(H6,G6/H6*100,U4) -> 68.965517 | J6: ='g1'!I95 -> 0 | K6: ='g1'!J95 -> 0 | L6: =IF(K6,J6/K6*100,U4) -> --- | M6: ='g1'!K95 -> 7 | N6: ='g1'!L95 -> 8 | O6: =IF(N6,M6/N6*100,U4) -> 87.5 | P6: ='g1'!M95 -> 1 | Q6: ='g1'!N95 -> 5 | R6: ='g1'!O95 -> 4 | S6: ='g1'!P95 -> -13 | U6: ---
A7: ='g1'!A122 -> S.G.Alexander | B7: ='g1'!B122 -> 31 | C7: ='g1'!C122 -> 4 | D7: ='g1'!D122 -> 0 | E7: ='g1'!E122 -> 1 | F7: ='g1'!F122 -> 1 | G7: ='g1'!G122 -> 11 | H7: ='g1'!H122 -> 25 | I7: =IF(H7,G7/H7*100,U5) -> 44 | J7: ='g1'!I122 -> 0 | K7: ='g1'!J122 -> 0 | L7: =IF(K7,J7/K7*100,U5) -> --- | M7: ='g1'!K122 -> 9 | N7: ='g1'!L122 -> 10 | O7: =IF(N7,M7/N7*100,U5) -> 90 | P7: ='g1'!M122 -> 0 | Q7: ='g1'!N122 -> 1 | R7: ='g1'!O122 -> 1 | S7: ='g1'!P122 -> -18 | U7: ---
A8: ='g1'!A148 -> S.G.Alexander | B8: ='g1'!B148 -> 17 | C8: ='g1'!C148 -> 6 | D8: ='g1'!D148 -> 2 | E8: ='g1'!E148 -> 1 | F8: ='g1'!F148 -> 1 | G8: ='g1'!G148 -> 5 | H8: ='g1'!H148 -> 14 | I8: =IF(H8,G8/H8*100,U6) -> 35.714286 | J8: ='g1'!I148 -> 0 | K8: ='g1'!J148 -> 0 | L8: =IF(K8,J8/K8*100,U6) -> --- | M8: ='g1'!K148 -> 7 | N8: ='g1'!L148 -> 7 | O8: =IF(N8,M8/N8*100,U6) -> 100 | P8: ='g1'!M148 -> 0 | Q8: ='g1'!N148 -> 6 | R8: ='g1'!O148 -> 2 | S8: ='g1'!P148 -> 8 | U8: ---
A9: ='g1'!A174 -> S.G.Alexander | B9: ='g1'!B174 -> 26 | C9: ='g1'!C174 -> 4 | D9: ='g1'!D174 -> 7 | E9: ='g1'!E174 -> 1 | F9: ='g1'!F174 -> 0 | G9: ='g1'!G174 -> 8 | H9: ='g1'!H174 -> 15 | I9: =IF(H9,G9/H9*100,U7) -> 53.333333 | J9: ='g1'!I174 -> 0 | K9: ='g1'!J174 -> 1 | L9: =IF(K9,J9/K9*100,U7) -> 0 | M9: ='g1'!K174 -> 10 | N9: ='g1'!L174 -> 12 | O9: =IF(N9,M9/N9*100,U7) -> 83.333333 | P9: ='g1'!M174 -> 0 | Q9: ='g1'!N174 -> 6 | R9: ='g1'!O174 -> 0 | S9: ='g1'!P174 -> 1 | U9: ---
A10: Average | B10: =AVERAGE(B3:B9) -> 39.857143 | C10: =AVERAGE(C3:C9) -> 4.4285714 | D10: =AVERAGE(D3:D9) -> 4 | E10: =AVERAGE(E3:E9) -> 1.7142857 | F10: =AVERAGE(F3:F9) -> 2 | G10: =AVERAGE(G3:G9) -> 13.285714 | H10: =AVERAGE(H3:H9) -> 23.571429 | I10: =IF(H10,G10/H10*100,U8) -> 56.363636 | J10: =AVERAGE(J3:J9) -> 0.14285714 | K10: =AVERAGE(K3:K9) -> 0.42857143 | L10: =IF(K10,J10/K10*100,U8) -> 33.333333 | M10: =AVERAGE(M3:M9) -> 13.142857 | N10: =AVERAGE(N3:N9) -> 14 | O10: =IF(N10,M10/N10*100,U8) -> 93.877551 | P10: =AVERAGE(P3:P9) -> 0.57142857 | Q10: =AVERAGE(Q3:Q9) -> 4.8571429 | R10: =AVERAGE(R3:R9) -> 2.5714286 | S10: =AVERAGE(S3:S9) -> 3 | U10: ---
A11: D.Mitchell | U11: ---
A12: game | B12: 得分 | C12: 篮板 | D12: 助攻 | E12: 盖帽 | F12: 抢断 | G12: FGM | H12: FGA | I12: FG% | J12: 3PTM | K12: 3PTA | L12: 3PT% | M12: FTM | N12: FTA | O12: FT% | P12: 进攻篮板 | Q12: 犯规 | R12: 失误 | S12: 正负值/分差 | U12: ---
A13: ='g1'!A15 -> D.Mitchell | B13: ='g1'!B15 -> 34 | C13: ='g1'!C15 -> 4 | D13: ='g1'!D15 -> 6 | E13: ='g1'!E15 -> 1 | F13: ='g1'!F15 -> 1 | G13: ='g1'!G15 -> 12 | H13: ='g1'!H15 -> 21 | I13: =IF(H13,G13/H13*100,U11) -> 57.142857 | J13: ='g1'!I15 -> 0 | K13: ='g1'!J15 -> 1 | L13: =IF(K13,J13/K13*100,U11) -> 0 | M13: ='g1'!K15 -> 10 | N13: ='g1'!L15 -> 10 | O13: =IF(N13,M13/N13*100,U11) -> 100 | P13: ='g1'!M15 -> 0 | Q13: ='g1'!N15 -> 5 | R13: ='g1'!O15 -> 2 | S13: ='g1'!P15 -> 9 | U13: ---
A14: ='g1'!A42 -> D.Mitchell | B14: ='g1'!B42 -> 29 | C14: ='g1'!C42 -> 5 | D14: ='g1'!D42 -> 13 | E14: ='g1'!E42 -> 3 | F14: ='g1'!F42 -> 2 | G14: ='g1'!G42 -> 10 | H14: ='g1'!H42 -> 30 | I14: =IF(H14,G14/H14*100,U12) -> 33.333333 | J14: ='g1'!I42 -> 1 | K14: ='g1'!J42 -> 2 | L14: =IF(K14,J14/K14*100,U12) -> 50 | M14: ='g1'!K42 -> 8 | N14: ='g1'!L42 -> 11 | O14: =IF(N14,M14/N14*100,U12) -> 72.727273 | P14: ='g1'!M42 -> 1 | Q14: ='g1'!N42 -> 6 | R14: ='g1'!O42 -> 4 | S14: ='g1'!P42 -> 12 | U14: ---
A15: ='g1'!A69 -> D.Mitchell | B15: ='g1'!B69 -> 42 | C15: ='g1'!C69 -> 3 | D15: ='g1'!D69 -> 1 | E15: ='g1'!E69 -> 1 | F15: ='g1'!F69 -> 2 | G15: ='g1'!G69 -> 17 | H15: ='g1'!H69 -> 39 | I15: =IF(H15,G15/H15*100,U13) -> 43.589744 | J15: ='g1'!I69 -> 0 | K15: ='g1'!J69 -> 0 | L15: =IF(K15,J15/K15*100,U13) -> --- | M15: ='g1'!K69 -> 8 | N15: ='g1'!L69 -> 9 | O15: =IF(N15,M15/N15*100,U13) -> 88.888889 | P15: ='g1'!M69 -> 0 | Q15: ='g1'!N69 -> 4 | R15: ='g1'!O69 -> 1 | S15: ='g1'!P69 -> -7 | U15: ---
A16: ='g1'!A96 -> D.Mitchell | B16: ='g1'!B96 -> 29 | C16: ='g1'!C96 -> 4 | D16: ='g1'!D96 -> 10 | E16: ='g1'!E96 -> 1 | F16: ='g1'!F96 -> 1 | G16: ='g1'!G96 -> 10 | H16: ='g1'!H96 -> 23 | I16: =IF(H16,G16/H16*100,U14) -> 43.478261 | J16: ='g1'!I96 -> 3 | K16: ='g1'!J96 -> 5 | L16: =IF(K16,J16/K16*100,U14) -> 60 | M16: ='g1'!K96 -> 6 | N16: ='g1'!L96 -> 7 | O16: =IF(N16,M16/N16*100,U14) -> 85.714286 | P16: ='g1'!M96 -> 0 | Q16: ='g1'!N96 -> 4 | R16: ='g1'!O96 -> 2 | S16: ='g1'!P96 -> -17 | U16: ---
A17: ='g1'!A123 -> D.Mitchell | B17: ='g1'!B123 -> 18 | C17: ='g1'!C123 -> 5 | D17: ='g1'!D123 -> 3 | E17: ='g1'!E123 -> 1 | F17: ='g1'!F123 -> 0 | G17: ='g1'!G123 -> 5 | H17: ='g1'!H123 -> 13 | I17: =IF(H17,G17/H17*100,U15) -> 38.461538 | J17: ='g1'!I123 -> 0 | K17: ='g1'!J123 -> 0 | L17: =IF(K17,J17/K17*100,U15) -> --- | M17: ='g1'!K123 -> 8 | N17: ='g1'!L123 -> 8 | O17: =IF(N17,M17/N17*100,U15) -> 100 | P17: ='g1'!M123 -> 0 | Q17: ='g1'!N123 -> 2 | R17: ='g1'!O123 -> 3 | S17: ='g1'!P123 -> -16 | U17: ---
A18: ='g1'!A149 -> D.Mitchell | B18: ='g1'!B149 -> 51 | C18: ='g1'!C149 -> 8 | D18: ='g1'!D149 -> 8 | E18: ='g1'!E149 -> 2 | F18: ='g1'!F149 -> 4 | G18: ='g1'!G149 -> 19 | H18: ='g1'!H149 -> 36 | I18: =IF(H18,G18/H18*100,U16) -> 52.777778 | J18: ='g1'!I149 -> 1 | K18: ='g1'!J149 -> 3 | L18: =IF(K18,J18/K18*100,U16) -> 33.333333 | M18: ='g1'!K149 -> 12 | N18: ='g1'!L149 -> 13 | O18: =IF(N18,M18/N18*100,U16) -> 92.307692 | P18: ='g1'!M149 -> 1 | Q18: ='g1'!N149 -> 2 | R18: ='g1'!O149 -> 1 | S18: ='g1'!P149 -> 14 | U18: ---
A19: ='g1'!A175 -> D.Mitchell | B19: ='g1'!B175 -> 58 | C19: ='g1'!C175 -> 7 | D19: ='g1'!D175 -> 8 | E19: ='g1'!E175 -> 2 | F19: ='g1'!F175 -> 2 | G19: ='g1'!G175 -> 20 | H19: ='g1'!H175 -> 36 | I19: =IF(H19,G19/H19*100,U17) -> 55.555556 | J19: ='g1'!I175 -> 8 | K19: ='g1'!J175 -> 12 | L19: =IF(K19,J19/K19*100,U17) -> 66.666667 | M19: ='g1'!K175 -> 10 | N19: ='g1'!L175 -> 10 | O19: =IF(N19,M19/N19*100,U17) -> 100 | P19: ='g1'!M175 -> 2 | Q19: ='g1'!N175 -> 3 | R19: ='g1'!O175 -> 2 | S19: ='g1'!P175 -> 11 | U19: ---
A20: Average | B20: =AVERAGE(B13:B19) -> 37.285714 | C20: =AVERAGE(C13:C19) -> 5.1428571 | D20: =AVERAGE(D13:D19) -> 7 | E20: =AVERAGE(E13:E19) -> 1.5714286 | F20: =AVERAGE(F13:F19) -> 1.7142857 | G20: =AVERAGE(G13:G19) -> 13.285714 | H20: =AVERAGE(H13:H19) -> 28.285714 | I20: =IF(H20,G20/H20*100,U18) -> 46.969697 | J20: =AVERAGE(J13:J19) -> 1.8571429 | K20: =AVERAGE(K13:K19) -> 3.2857143 | L20: =IF(K20,J20/K20*100,U18) -> 56.521739 | M20: =AVERAGE(M13:M19) -> 8.8571429 | N20: =AVERAGE(N13:N19) -> 9.7142857 | O20: =IF(N20,M20/N20*100,U18) -> 91.176471 | P20: =AVERAGE(P13:P19) -> 0.57142857 | Q20: =AVERAGE(Q13:Q19) -> 3.7142857 | R20: =AVERAGE(R13:R19) -> 2.1428571 | S20: =AVERAGE(S13:S19) -> 0.85714286 | U20: ---
U21: ---
U22: ---
U23: ---
U24: ---
U25: ---
A26: D.Booker | U26: ---
A27: game | B27: 得分 | C27: 篮板 | D27: 助攻 | E27: 盖帽 | F27: 抢断 | G27: FGM | H27: FGA | I27: FG% | J27: 3PTM | K27: 3PTA | L27: 3PT% | M27: FTM | N27: FTA | O27: FT% | P27: 进攻篮板 | Q27: 犯规 | R27: 失误 | S27: 正负值/分差 | U27: ---
A28: ='g1'!A16 -> D.Booker | B28: ='g1'!B16 -> 12 | C28: ='g1'!C16 -> 8 | D28: ='g1'!D16 -> 10 | E28: ='g1'!E16 -> 0 | F28: ='g1'!F16 -> 1 | G28: ='g1'!G16 -> 4 | H28: ='g1'!H16 -> 15 | I28: =IF(H28,G28/H28*100,U26) -> 26.666667 | J28: ='g1'!I16 -> 4 | K28: ='g1'!J16 -> 8 | L28: =IF(K28,J28/K28*100,U26) -> 50 | M28: ='g1'!K16 -> 0 | N28: ='g1'!L16 -> 0 | O28: =IF(N28,M28/N28*100,U26) -> --- | P28: ='g1'!M16 -> 0 | Q28: ='g1'!N16 -> 4 | R28: ='g1'!O16 -> 0 | S28: ='g1'!P16 -> 18 | U28: ---
A29: ='g1'!A43 -> D.Booker | B29: ='g1'!B43 -> 11 | C29: ='g1'!C43 -> 13 | D29: ='g1'!D43 -> 7 | E29: ='g1'!E43 -> 3 | F29: ='g1'!F43 -> 1 | G29: ='g1'!G43 -> 4 | H29: ='g1'!H43 -> 9 | I29: =IF(H29,G29/H29*100,U27) -> 44.444444 | J29: ='g1'!I43 -> 1 | K29: ='g1'!J43 -> 3 | L29: =IF(K29,J29/K29*100,U27) -> 33.333333 | M29: ='g1'!K43 -> 2 | N29: ='g1'!L43 -> 3 | O29: =IF(N29,M29/N29*100,U27) -> 66.666667 | P29: ='g1'!M43 -> 0 | Q29: ='g1'!N43 -> 6 | R29: ='g1'!O43 -> 0 | S29: ='g1'!P43 -> 0 | U29: ---
A30: ='g1'!A70 -> D.Booker | B30: ='g1'!B70 -> 55 | C30: ='g1'!C70 -> 6 | D30: ='g1'!D70 -> 4 | E30: ='g1'!E70 -> 3 | F30: ='g1'!F70 -> 2 | G30: ='g1'!G70 -> 19 | H30: ='g1'!H70 -> 26 | I30: =IF(H30,G30/H30*100,U28) -> 73.076923 | J30: ='g1'!I70 -> 7 | K30: ='g1'!J70 -> 11 | L30: =IF(K30,J30/K30*100,U28) -> 63.636364 | M30: ='g1'!K70 -> 10 | N30: ='g1'!L70 -> 11 | O30: =IF(N30,M30/N30*100,U28) -> 90.909091 | P30: ='g1'!M70 -> 0 | Q30: ='g1'!N70 -> 3 | R30: ='g1'!O70 -> 1 | S30: ='g1'!P70 -> -11 | U30: ---
A31: ='g1'!A97 -> D.Booker | B31: ='g1'!B97 -> 19 | C31: ='g1'!C97 -> 5 | D31: ='g1'!D97 -> 3 | E31: ='g1'!E97 -> 1 | F31: ='g1'!F97 -> 0 | G31: ='g1'!G97 -> 7 | H31: ='g1'!H97 -> 11 | I31: =IF(H31,G31/H31*100,U29) -> 63.636364 | J31: ='g1'!I97 -> 4 | K31: ='g1'!J97 -> 8 | L31: =IF(K31,J31/K31*100,U29) -> 50 | M31: ='g1'!K97 -> 1 | N31: ='g1'!L97 -> 1 | O31: =IF(N31,M31/N31*100,U29) -> 100 | P31: ='g1'!M97 -> 1 | Q31: ='g1'!N97 -> 5 | R31: ='g1'!O97 -> 4 | S31: ='g1'!P97 -> -10 | U31: ---
A32: ='g1'!A124 -> D.Booker | B32: ='g1'!B124 -> 5 | C32: ='g1'!C124 -> 4 | D32: ='g1'!D124 -> 1 | E32: ='g1'!E124 -> 0 | F32: ='g1'!F124 -> 0 | G32: ='g1'!G124 -> 2 | H32: ='g1'!H124 -> 12 | I32: =IF(H32,G32/H32*100,U30) -> 16.666667 | J32: ='g1'!I124 -> 1 | K32: ='g1'!J124 -> 6 | L32: =IF(K32,J32/K32*100,U30) -> 16.666667 | M32: ='g1'!K124 -> 0 | N32: ='g1'!L124 -> 0 | O32: =IF(N32,M32/N32*100,U30) -> --- | P32: ='g1'!M124 -> 0 | Q32: ='g1'!N124 -> 2 | R32: ='g1'!O124 -> 4 | S32: ='g1'!P124 -> -26 | U32: ---
A33: ='g1'!A150 -> D.Booker | B33: ='g1'!B150 -> 48 | C33: ='g1'!C150 -> 8 | D33: ='g1'!D150 -> 2 | E33: ='g1'!E150 -> 1 | F33: ='g1'!F150 -> 1 | G33: ='g1'!G150 -> 17 | H33: ='g1'!H150 -> 20 | I33: =IF(H33,G33/H33*100,U31) -> 85 | J33: ='g1'!I150 -> 7 | K33: ='g1'!J150 -> 8 | L33: =IF(K33,J33/K33*100,U31) -> 87.5 | M33: ='g1'!K150 -> 7 | N33: ='g1'!L150 -> 7 | O33: =IF(N33,M33/N33*100,U31) -> 100 | P33: ='g1'!M150 -> 0 | Q33: ='g1'!N150 -> 4 | R33: ='g1'!O150 -> 0 | S33: ='g1'!P150 -> 10 | U33: ---
A34: ='g1'!A176 -> D.Booker | B34: ='g1'!B176 -> 18 | C34: ='g1'!C176 -> 7 | D34: ='g1'!D176 -> 5 | E34: ='g1'!E176 -> 3 | F34: ='g1'!F176 -> 0 | G34: ='g1'!G176 -> 7 | H34: ='g1'!H176 -> 14 | I34: =IF(H34,G34/H34*100,U32) -> 50 | J34: ='g1'!I176 -> 4 | K34: ='g1'!J176 -> 9 | L34: =IF(K34,J34/K34*100,U32) -> 44.444444 | M34: ='g1'!K176 -> 0 | N34: ='g1'!L176 -> 0 | O34: =IF(N34,M34/N34*100,U32) -> --- | P34: ='g1'!M176 -> 0 | Q34: ='g1'!N176 -> 4 | R34: ='g1'!O176 -> 0 | S34: ='g1'!P176 -> 12 | U34: ---
A35: Average | B35: =AVERAGE(B28:B34) -> 24 | C35: =AVERAGE(C28:C34) -> 7.2857143 | D35: =AVERAGE(D28:D34) -> 4.5714286 | E35: =AVERAGE(E28:E34) -> 1.5714286 | F35: =AVERAGE(F28:F34) -> 0.71428571 | G35: =AVERAGE(G28:G34) -> 8.5714286 | H35: =AVERAGE(H28:H34) -> 15.285714 | I35: =IF(H35,G35/H35*100,U33) -> 56.074766 | J35: =AVERAGE(J28:J34) -> 4 | K35: =AVERAGE(K28:K34) -> 7.5714286 | L35: =IF(K35,J35/K35*100,U33) -> 52.830189 | M35: =AVERAGE(M28:M34) -> 2.8571429 | N35: =AVERAGE(N28:N34) -> 3.1428571 | O35: =IF(N35,M35/N35*100,U33) -> 90.909091 | P35: =AVERAGE(P28:P34) -> 0.14285714 | Q35: =AVERAGE(Q28:Q34) -> 4 | R35: =AVERAGE(R28:R34) -> 1.2857143 | S35: =AVERAGE(S28:S34) -> -1 | U35: ---
U36: ---
U37: ---
U38: ---
U39: ---
U40: ---
...

Sheet Sheet3
A1: \ | B1: 得分 | C1: 篮板 | D1: 助攻 | E1: 盖帽 | F1: 抢断 | G1: FGM | H1: FGA | I1: FG% | J1: 3PTM | K1: 3PTA | L1: 3PT% | M1: FTM | N1: FTA | O1: FT% | P1: 进攻篮板 | Q1: 犯规 | R1: 失误 | S1: 正负值/分差
A2: CLE
A3: =Sheet2!A9 -> S.G.Alexander | B3: =Sheet2!B10 -> 39.857143 | C3: =Sheet2!C10 -> 4.4285714 | D3: =Sheet2!D10 -> 4 | E3: =Sheet2!E10 -> 1.7142857 | F3: =Sheet2!F10 -> 2 | G3: =Sheet2!G10 -> 13.285714 | H3: =Sheet2!H10 -> 23.571429 | I3: =Sheet2!I10 -> 56.363636 | ... S3: =Sheet2!S10 -> 3
A4: =Sheet2!A19 -> D.Mitchell | B4: =Sheet2!B20 -> 37.285714 | C4: =Sheet2!C20 -> 5.1428571 | D4: =Sheet2!D20 -> 7 | E4: =Sheet2!E20 -> 1.5714286 | F4: =Sheet2!F20 -> 1.7142857 | G4: =Sheet2!G20 -> 13.285714 | H4: =Sheet2!H20 -> 28.285714 | I4: =Sheet2!I20 -> 46.969697 | ... S4: =Sheet2!S20 -> 0.85714286
A5: =Sheet2!A34 -> D.Booker | B5: =Sheet2!B35 -> 24 | C5: =Sheet2!C35 -> 7.2857143 | D5: =Sheet2!D35 -> 4.5714286 | E5: =Sheet2!E35 -> 1.5714286 | F5: =Sheet2!F35 -> 0.71428571 | G5: =Sheet2!G35 -> 8.5714286 | H5: =Sheet2!H35 -> 15.285714 | I5: =Sheet2!I35 -> 56.074766 | ... S5: =Sheet2!S35 -> -1
A6: =Sheet2!A49 -> M.Robinson | B6: =Sheet2!B50 -> 18.428571 | C6: =Sheet2!C50 -> 10.285714 | D6: =Sheet2!D50 -> 5.7142857 | E6: =Sheet2!E50 -> 3.8571429 | F6: =Sheet2!F50 -> 0.57142857 | G6: =Sheet2!G50 -> 6.5714286 | H6: =Sheet2!H50 -> 12 | I6: =Sheet2!I50 -> 54.761905 | ... S6: =Sheet2!S50 -> 0
A7: =Sheet2!A64 -> W.Chamberlain | B7: =Sheet2!B65 -> 6.5714286 | C7: =Sheet2!C65 -> 9.8571429 | D7: =Sheet2!D65 -> 3.2857143 | E7: =Sheet2!E65 -> 4.4285714 | F7: =Sheet2!F65 -> 0.85714286 | G7: =Sheet2!G65 -> 3.1428571 | H7: =Sheet2!H65 -> 4.8571429 | I7: =Sheet2!I65 -> 64.705882 | ... S7: =Sheet2!S65 -> 0.14285714
A8: =Sheet2!A79 -> J.Brown | B8: =Sheet2!B80 -> 9.7142857 | C8: =Sheet2!C80 -> 4.1428571 | D8: =Sheet2!D80 -> 2.8571429 | E8: =Sheet2!E80 -> 1.4285714 | F8: =Sheet2!F80 -> 0.14285714 | G8: =Sheet2!G80 -> 3.8571429 | H8: =Sheet2!H80 -> 8.8571429 | I8: =Sheet2!I80 -> 43.548387 | ... S8: =Sheet2!S80 -> -8.5714286
A9: =Sheet2!A94 -> T.Rozier III | B9: =Sheet2!B95 -> 7.1428571 | C9: =Sheet2!C95 -> 2.2857143 | D9: =Sheet2!D95 -> 2.2857143 | E9: =Sheet2!E95 -> 0.57142857 | F9: =Sheet2!F95 -> 0.42857143 | G9: =Sheet2!G95 -> 2.7142857 | H9: =Sheet2!H95 -> 6.1428571 | I9: =Sheet2!I95 -> 44.186047 | ... S9: =Sheet2!S95 -> -9.4285714
A10: =Sheet2!A109 -> M.Wagner | B10: =Sheet2!B110 -> 6.7142857 | C10: =Sheet2!C110 -> 3.2857143 | D10: =Sheet2!D110 -> 0.71428571 | E10: =Sheet2!E110 -> 0.71428571 | F10: =Sheet2!F110 -> 0 | G10: =Sheet2!G110 -> 2.5714286 | H10: =Sheet2!H110 -> 3.7142857 | I10: =Sheet2!I110 -> 69.230769 | ... S10: =Sheet2!S110 -> -4.4285714
A11: =Sheet2!A124 -> E.Schmidt | B11: =Sheet2!B125 -> 5 | C11: =Sheet2!C125 -> 0.71428571 | D11: =Sheet2!D125 -> 3.5714286 | E11: =Sheet2!E125 -> 0.14285714 | F11: =Sheet2!F125 -> 0.28571429 | G11: =Sheet2!G125 -> 1.4285714 | H11: =Sheet2!H125 -> 2.5714286 | I11: =Sheet2!I125 -> 55.555556 | ... S11: =Sheet2!S125 -> 0.42857143
A12: =Sheet2!A266 -> CLE总计 | B12: =Sheet2!B275 -> 155.71429 | C12: =Sheet2!C275 -> 48.285714 | D12: =Sheet2!D275 -> 34.571429 | E12: =Sheet2!E275 -> 16.285714 | F12: =Sheet2!F275 -> 6.7142857 | G12: =Sheet2!G275 -> 55.857143 | H12: =Sheet2!H275 -> 107 | I12: =Sheet2!I275 -> 52.202937 | ... S12: =Sheet2!S275 -> -1.7142857
A13: NO
A14: =Sheet2!A139 -> Lonzo Ball | B14: =Sheet2!B140 -> 25.714286 | C14: =Sheet2!C140 -> 4.8571429 | D14: =Sheet2!D140 -> 9.7142857 | E14: =Sheet2!E140 -> 2.7142857 | F14: =Sheet2!F140 -> 1.5714286 | G14: =Sheet2!G140 -> 10.714286 | H14: =Sheet2!H140 -> 21.714286 | I14: =Sheet2!I140 -> 49.342105 | ... S14: =Sheet2!S140 -> 4.8571429
A15: =Sheet2!A154 -> N.A.Walker | B15: =Sheet2!B155 -> 30 | C15: =Sheet2!C155 -> 5.4285714 | D15: =Sheet2!D155 -> 5.5714286 | E15: =Sheet2!E155 -> 1.5714286 | F15: =Sheet2!F155 -> 1.1428571 | G15: =Sheet2!G155 -> 11.857143 | H15: =Sheet2!H155 -> 20.142857 | I15: =Sheet2!I155 -> 58.865248 | ... S15: =Sheet2!S155 -> 4.1428571
A16: =Sheet2!A169 -> B.Ingram | B16: =Sheet2!B170 -> 21.714286 | C16: =Sheet2!C170 -> 5.8571429 | D16: =Sheet2!D170 -> 10 | E16: =Sheet2!E170 -> 1 | F16: =Sheet2!F170 -> 1.1428571 | G16: =Sheet2!G170 -> 8.5714286 | H16: =Sheet2!H170 -> 16.428571 | I16: =Sheet2!I170 -> 52.173913 | ... S16: =Sheet2!S170 -> -0.28571429
A17: =Sheet2!A184 -> Z.Williamson | B17: =Sheet2!B185 -> 12.285714 | C17: =Sheet2!C185 -> 8.8571429 | D17: =Sheet2!D185 -> 2.8571429 | E17: =Sheet2!E185 -> 1.1428571 | F17: =Sheet2!F185 -> 1.7142857 | G17: =Sheet2!G185 -> 5.4285714 | H17: =Sheet2!H185 -> 11.571429 | I17: =Sheet2!I185 -> 46.91358 | ... S17: =Sheet2!S185 -> 6.1428571
A18: =Sheet2!A199 -> A.Drummond | B18: =Sheet2!B200 -> 21 | C18: =Sheet2!C200 -> 19.142857 | D18: =Sheet2!D200 -> 2.4285714 | E18: =Sheet2!E200 -> 0.57142857 | F18: =Sheet2!F200 -> 1.8571429 | G18: =Sheet2!G200 -> 9.8571429 | H18: =Sheet2!H200 -> 14.714286 | I18: =Sheet2!I200 -> 66.990291 | ... S18: =Sheet2!S200 -> 1
A19: =Sheet2!A214 -> J.Holiday | B19: =Sheet2!B215 -> 21.571429 | C19: =Sheet2!C215 -> 3.1428571 | D19: =Sheet2!D215 -> 4 | E19: =Sheet2!E215 -> 0.57142857 | F19: =Sheet2!F215 -> 1.8571429 | G19: =Sheet2!G215 -> 8.5714286 | H19: =Sheet2!H215 -> 16.714286 | I19: =Sheet2!I215 -> 51.282051 | ... S19: =Sheet2!S215 -> 2
A20: =Sheet2!A229 -> S.Mcdaniels | B20: =Sheet2!B230 -> 10 | C20: =Sheet2!C230 -> 1.8571429 | D20: =Sheet2!D230 -> 3.8571429 | E20: =Sheet2!E230 -> 0 | F20: =Sheet2!F230 -> 0.85714286 | G20: =Sheet2!G230 -> 3.8571429 | H20: =Sheet2!H230 -> 7.8571429 | I20: =Sheet2!I230 -> 49.090909 | ... S20: =Sheet2!S230 -> 0.71428571
A21: =Sheet2!A244 -> J.Hart | B21: =Sheet2!B245 -> 7.1428571 | C21: =Sheet2!C245 -> 1.1428571 | D21: =Sheet2!D245 -> 1.2857143 | E21: =Sheet2!E245 -> 0.28571429 | F21: =Sheet2!F245 -> 0.42857143 | G21: =Sheet2!G245 -> 2.8571429 | H21: =Sheet2!H245 -> 6 | I21: =Sheet2!I245 -> 47.619048 | ... S21: =Sheet2!S245 -> 1.5714286
A22: =Sheet2!A259 -> D.Gallinari | B22: =Sheet2!B260 -> 4.8571429 | C22: =Sheet2!C260 -> 2.4285714 | D22: =Sheet2!D260 -> 1.1428571 | E22: =Sheet2!E260 -> 0.85714286 | F22: =Sheet2!F260 -> 1 | G22: =Sheet2!G260 -> 1.8571429 | H22: =Sheet2!H260 -> 4.7142857 | I22: =Sheet2!I260 -> 39.393939 | ... S22: =Sheet2!S260 -> 0.14285714
A23: =Sheet2!A281 -> NO总计 | B23: =Sheet2!B290 -> 157.42857 | C23: =Sheet2!C290 -> 55.714286 | D23: =Sheet2!D290 -> 41.142857 | E23: =Sheet2!E290 -> 8.8571429 | F23: =Sheet2!F290 -> 12.857143 | G23: =Sheet2!G290 -> 64.857143 | H23: =Sheet2!H290 -> 123.57143 | I23: =Sheet2!I290 -> 52.485549 | ... S23: =Sheet2!S290 -> 1.7142857
